Workbook

Sheet 검토_가이드
A1: CRMLN 반기(1년 2회) 측정결과 검토 템플릿 — 사용 가이드
A2: KDCA NMRL(Lab 509) · HDL-C / LDL-C(β-quantification) · Claude for Excel 연계용
A4: ① 사용 방법 (매 회차)
A5: 1. [결과정리] 시트의 R1·R2·R3 열(Day1: E·F·G / Day2: Q·R·S)에 새 회차 측정값을 붙여넣습니다.
A6: 2. CS 검체의 채택 2반복 셀이 자동으로 노란색으로 표시됩니다(선택 기준: 종합 BF+HDL 상대편차·균형, 검체별 동일 R index 잠금).
A7: 3. QC·Control(NIST·CFS·Q2)의 bias가 CRMLN member 기준을 초과하면 해당 bias 셀이 자동으로 빨간색으로 표시됩니다.
A8: 4. 값만 바꾸면 색상이 즉시 재계산되므로 별도 조작이 필요 없습니다(수식·조건부 서식 기반). 선택 기준을 바꿔 비교하려면 [제출결과_선택검토] 시트의 선택 옵션(C4)을 사용합니다.
A10: ② CRMLN member laboratory 판정 기준 (자동 빨강 표시 기준)
A11: 항목 | B11: 관리물질 | C11: 기준 | D11: 비고
A12: NIST (TC) | B12: NIST1·2 | C12: bias ±1% | D12: SRM 1951 정확도 앵커
A13: BF (하부분획) | B13: CFS·Q2 | C13: bias ±2% | D13: LDL 기준 준용(BF=LDL 상류)
A14: HDL-C | B14: CFS·Q2 | C14: bias ±1 mg/dL | D14: 저농도 → mg/dL로 판정
A15: LDL-C | B15: CFS·Q2 | C15: bias ±2%
A17: ③ 선택(채택) 로직
A18: · 각 CS 검체·Day에서 R1/R2/R3 중 1개를 제외하고 2개를 채택합니다.
A19: · 제외 기준: BF·HDL 각각 median 대비 상대편차(%)의 합이 가장 큰 replicate(=이상치)를 제외 — 기본(종합) 옵션이며, [제출결과_선택검토] 시트에서 12종 옵션으로 변경·비교할 수 있습니다.
A20: · BF·HDL·LDL은 동일 R index로 잠금 채택(LDL = BF − HDL 정합 유지).
A21: · QC·Control은 제출 대상이 아니므로 선택·표시하지 않습니다(전체 3반복 사용).
A22: · 방법론 원칙: 정밀도 기반 선택이며, 결과를 유리하게 만들기 위한 선택은 지양.
A24: ④ [제출결과_선택검토] 시트 — 선택 옵션별 제출결과 검토
A25: · 목적: [2026-07_결과정리] 시트와 동일한 DAY1·DAY2 표 양식으로 선택 결과를 재현하고, 선택 옵션을 바꿔가며 채택값·정밀도를 비교합니다.
A26: · 사용법: [C4] 드롭다운에서 옵션을 고르면 ① 표의 채택 셀(노란색)·제외 셀(회색)·평균·CV·판정과 ②~④ 요약이 즉시 재계산됩니다.
A27: · '수동 지정' 선택 시 부록 ⑤ 표의 S열(수동 제외R)에 검체·Day별로 R1/R2/R3을 직접 입력합니다.
A29: 구분 | B29: 선택 옵션 | C29: 제외/채택 로직
A30: 정밀도 기준 (권장) | B30: 종합 (BF+HDL 상대편차) · 균형 [기본] | C30: median 대비 BF+HDL 상대편차(%) 합이 가장 큰 replicate 1개 제외
B31: LDL 결과 우선 (LDL 편차 최소) | C31: LDL 상대편차가 가장 큰 replicate 1개 제외
B32: BF(하부분획) 우선 | C32: BF 상대편차가 가장 큰 replicate 1개 제외
B33: HDL 우선 | C33: HDL 상대편차가 가장 큰 replicate 1개 제외
B34: 3항목 종합 (BF+HDL+LDL) | C34: BF+HDL+LDL 상대편차 합이 가장 큰 replicate 1개 제외
B35: 최소분산 쌍 (가장 근접 2개 채택) | C35: 잔여 2개의 상대간격 합(BF+HDL+LDL)이 최소가 되도록 1개 제외
A36: 방향성 (민감도·what-if) | B36: HDL 높은값 우선 (상위 2개 채택) | C36: HDL 최저값 replicate 제외
B37: HDL 낮은값 우선 (하위 2개 채택) | C37: HDL 최고값 replicate 제외
B38: BF 높은값 우선 (상위 2개 채택) | C38: BF 최저값 replicate 제외
B39: BF 낮은값 우선 (하위 2개 채택) | C39: BF 최고값 replicate 제외
A40: 기타 (검토용) | B40: 3반복 전체 (참고·선택 미적용) | C40: 제외 없이 R1·R2·R3 평균 사용
B41: 수동 지정 (직접 입력) | C41: 부록 ⑤ S열에 지정한 replicate 제외
A43: · 기본(종합) 대비 비교 컬럼: 각 Day 블록 오른쪽에 [기본(종합) 채택 / Δ 평균 / 기본 CV% / Δ CV%p]가 표시됩니다.
A44: - Δ 평균 ≠ 0 → 기본 선택과 채택 조합이 달라진 검체·Day (노란 강조)
A45: - Δ CV%p < 0(초록) 정밀도 개선 · > 0(주황) 정밀도 악화
A46: · 시트 구성: ① 선택 결과(결과정리 양식) → ② 제출용 요약 → ③ 판정 기준 → ④ 검토 요약 → ⑤ 부록(선택 계산 근거·수동 입력)
...

Sheet RESULT(Conc)_DAY1
D2: CON | E2: ABS
A3: B1 | B3: Standard | D3: 0 | E3: 0.0007 | F3: =(E3+0.00135)/0.001819 -> 1.1269929 | G3: =(E3+0.000638)/0.001817 -> 0.73637865 | H3: =D3-G3 -> -0.73637865
A4: B2 | B4: Standard | D4: 0 | E4: 0 | F4: =(E4+0.00135)/0.001819 -> 0.74216603 | G4: =(E4+0.000638)/0.001817 -> 0.35112823 | H4: =D4-G4 -> -0.35112823
A5: 25_1 | B5: Standard | D5: 26.59 | F5: =(E5+0.00135)/0.001819 -> 0.74216603 | G5: =(E5+0.000638)/0.001817 -> 0.35112823 | H5: =D5-G5 -> 26.238872
A6: 25_2 | B6: Standard | D6: 26.59 | E6: 0.0464 | F6: =(E6+0.00135)/0.001819 -> 26.250687 | G6: =(E6+0.000638)/0.001817 -> 25.887727 | H6: =D6-G6 -> 0.70227298
A7: 50_1 | B7: Standard | D7: 53 | F7: =(E7+0.00135)/0.001819 -> 0.74216603 | G7: =(E7+0.000638)/0.001817 -> 0.35112823 | H7: =D7-G7 -> 52.648872
A8: 50_2 | B8: Standard | D8: 53 | E8: 0.0955 | F8: =(E8+0.00135)/0.001819 -> 53.24354 | G8: =(E8+0.000638)/0.001817 -> 52.910292 | H8: =D8-G8 -> 0.08970831
A9: 100_1 | B9: Standard | D9: 106.08 | F9: =(E9+0.00135)/0.001819 -> 0.74216603 | G9: =(E9+0.000638)/0.001817 -> 0.35112823 | H9: =D9-G9 -> 105.72887
A10: 100_2 | B10: Standard | D10: 106.08 | E10: 0.1907 | F10: =(E10+0.00135)/0.001819 -> 105.57999 | G10: =(E10+0.000638)/0.001817 -> 105.30435 | H10: =D10-G10 -> 0.77565217
A11: 200_1 | B11: Standard | D11: 212.8 | E11: 0.3855 | F11: =(E11+0.00135)/0.001819 -> 212.6718 | G11: =(E11+0.000638)/0.001817 -> 212.51403 | H11: =D11-G11 -> 0.28596588
A12: 200_2 | B12: Standard | D12: 212.8 | E12: 0.3866 | F12: =(E12+0.00135)/0.001819 -> 213.27653 | G12: =(E12+0.000638)/0.001817 -> 213.11943 | H12: =D12-G12 -> -0.31942763
A13: 300_1 | B13: Standard | D13: 319.43 | E13: 0.5806 | F13: =(E13+0.00135)/0.001819 -> 319.92853 | G13: =(E13+0.000638)/0.001817 -> 319.88883 | H13: =D13-G13 -> -0.45882774
A14: 300_2 | B14: Standard | D14: 319.43 | F14: =(E14+0.00135)/0.001819 -> 0.74216603 | G14: =(E14+0.000638)/0.001817 -> 0.35112823 | H14: =D14-G14 -> 319.07887
A15: 400_1 | B15: Standard | D15: 427.25 | F15: =(E15+0.00135)/0.001819 -> 0.74216603 | G15: =(E15+0.000638)/0.001817 -> 0.35112823 | H15: =D15-G15 -> 426.89887
A16: 400_2 | B16: Standard | D16: 427.25 | E16: 0.7751 | F16: =(E16+0.00135)/0.001819 -> 426.85542 | G16: =(E16+0.000638)/0.001817 -> 426.93341 | H16: =D16-G16 -> 0.31659329
I17: STANDARD 제조일: 2025-10-22 | M17: * 실험일 : 2026-06-18 *실험담당 : 이현애
M18: * Abs 측정장비 :Shimadzu UV-2700
A19: NIST1_1 | B19: Unknown | D19: =(E19+0.000638)/0.001817 -> 154.45129 | E19: 0.28 | I19: A.value | J19: R1 | K19: R2 | L19: R3 | M19: mean | N19: stdev | O19: cv | P19: bias
A20: NIST1_2 | B20: Unknown | D20: =(E20+0.000638)/0.001817 -> 154.45129 | E20: 0.28 | G20: QC | H20: NIST1 | I20: 154.6 | J20: =D19 -> 154.45129 | K20: =D20 -> 154.45129 | L20: =D21 -> 155.66208 | M20: =AVERAGE(J20:L20) -> 154.85489 | N20: =STDEV(J20:L20) -> 0.69904821 | O20: =N20/M20*100 -> 0.45142146 | P20: =(M20-I20)/I20*100 -> 0.16486999
A21: NIST1_3 | B21: Unknown | D21: =(E21+0.000638)/0.001817 -> 155.66208 | E21: 0.2822
D22: =(E22+0.000638)/0.001817 -> 0.35112823 | G22: BF Control | H22: CFS 21-01 | I22: 169.55748 | J22: =D25 -> 168.76059 | K22: =D26 -> 171.01706 | L22: =D27 -> 170.68685 | M22: =AVERAGE(J22:L22) -> 170.15483 | N22: =STDEV(J22:L22) -> 1.2186831 | O22: =N22/M22*100 -> 0.71622008 | P22: =(M22-I22)/I22*100 -> 0.35230167
D23: =(E23+0.000638)/0.001817 -> 0.35112823 | H23: Q2 | I23: 196.2 | J23: =D28 -> 198.75509 | K23: =D29 -> 198.75509 | L23: =D30 -> 198.53495 | M23: =AVERAGE(J23:L23) -> 198.68171 | N23: =STDEV(J23:L23) -> 0.12709967 | O23: =N23/M23*100 -> 0.063971502 | P23: =(M23-I23)/I23*100 -> 1.2648878
D24: =(E24+0.000638)/0.001817 -> 0.35112823 | G24: BF Sample | H24: CS 01-01 | J24: =D31 -> 159.67969 | K24: =D32 -> 160.17501 | L24: =D33 -> 159.40451 | M24: =AVERAGE(J24:L24) -> 159.75307 | N24: =STDEV(J24:L24) -> 0.39045674 | O24: =N24/M24*100 -> 0.24441266 | P24: =(M24-I24)/I24*100 -> #DIV/0!
A25: BF CFS2101_1 | B25: Unknown | D25: =(E25+0.000638)/0.001817 -> 168.76059 | E25: 0.306 | H25: CS 01-02 | J25: =D34 -> 159.78976 | K25: =D35 -> 160.34012 | L25: =D36 -> 160.00991 | M25: =AVERAGE(J25:L25) -> 160.0466 | N25: =STDEV(J25:L25) -> 0.27700732 | O25: =N25/M25*100 -> 0.17307917 | P25: =(M25-I25)/I25*100 -> #DIV/0!
A26: BF CFS2101_2 | B26: Unknown | D26: =(E26+0.000638)/0.001817 -> 171.01706 | E26: 0.3101 | H26: CS 02-01 | J26: =D37 -> 239.81178 | K26: =D38 -> 240.85746 | L26: =D39 -> 239.81178 | M26: =AVERAGE(J26:L26) -> 240.16034 | N26: =STDEV(J26:L26) -> 0.60372345 | O26: =N26/M26*100 -> 0.2513835 | P26: =(M26-I26)/I26*100 -> #DIV/0!
A27: BF CFS2101_3 | B27: Unknown | D27: =(E27+0.000638)/0.001817 -> 170.68685 | E27: 0.3095 | H27: CS 02-02 | J27: =D40 -> 240.3071 | K27: =D41 -> 239.70171 | L27: =D42 -> 240.52724 | M27: =AVERAGE(J27:L27) -> 240.17868 | N27: =STDEV(J27:L27) -> 0.42748781 | O27: =N27/M27*100 -> 0.17798741 | P27: =(M27-I27)/I27*100 -> #DIV/0!
A28: BF Q2_1 | B28: Unknown | D28: =(E28+0.000638)/0.001817 -> 198.75509 | E28: 0.3605 | H28: CS 03-01 | J28: =D43 -> 132.7672 | K28: =D44 -> 132.49202 | L28: =D45 -> 132.49202 | M28: =AVERAGE(J28:L28) -> 132.58375 | N28: =STDEV(J28:L28) -> 0.15887459 | O28: =N28/M28*100 -> 0.11982962 | P28: =(M28-I28)/I28*100 -> #DIV/0!
A29: BF Q2_2 | B29: Unknown | D29: =(E29+0.000638)/0.001817 -> 198.75509 | E29: 0.3605 | H29: CS 03-02 | J29: =D46 -> 131.83159 | K29: =D47 -> 132.32691 | L29: =D48 -> 132.43698 | M29: =AVERAGE(J29:L29) -> 132.1985 | N29: =STDEV(J29:L29) -> 0.3224802 | O29: =N29/M29*100 -> 0.24393636 | P29: =(M29-I29)/I29*100 -> #DIV/0!
A30: BF Q2_3 | B30: Unknown | D30: =(E30+0.000638)/0.001817 -> 198.53495 | E30: 0.3601 | G30: HDL Control x1.09 | H30: CFS 21-01 | I30: 49.006709 | J30: =D49*1.09 -> 48.493902 | K30: =D50*1.09 -> 48.733858 | L30: =D51*1.09 -> 48.553891 | M30: =AVERAGE(J30:L30) -> 48.593884 | N30: =STDEV(J30:L30) -> 0.12487705 | O30: =N30/M30*100 -> 0.256981 | P30: =(M30-I30)/I30*100 -> -0.84238539
A31: BF CS 0101_1 | B31: Unknown | D31: =(E31+0.000638)/0.001817 -> 159.67969 | E31: 0.2895 | H31: Q2 | I31: 58.3 | J31: =D52*1.09 -> 57.912174 | K31: =D53*1.09 -> 57.55224 | L31: =D54*1.09 -> 58.032152 | M31: =AVERAGE(J31:L31) -> 57.832189 | N31: =STDEV(J31:L31) -> 0.24975409 | O31: =N31/M31*100 -> 0.43186001 | P31: =(M31-I31)/I31*100 -> -0.80242094
A32: BF CS 0101_2 | B32: Unknown | D32: =(E32+0.000638)/0.001817 -> 160.17501 | E32: 0.2904 | G32: HDL Sample x1.09 | H32: CS 01-01 | J32: =D55*1.09 -> 46.094342 | K32: =D56*1.09 -> 46.21432 | L32: =D57*1.09 -> 46.334298 | M32: =AVERAGE(J32:L32) -> 46.21432 | N32: =STDEV(J32:L32) -> 0.11997799 | O32: =N32/M32*100 -> 0.25961214 | P32: =(M32-I32)/I32*100 -> #DIV/0!
A33: BF CS 0101_3 | B33: Unknown | D33: =(E33+0.000638)/0.001817 -> 159.40451 | E33: 0.289 | H33: CS 01-02 | J33: =D58*1.09 -> 45.61443 | K33: =D59*1.09 -> 45.854386 | L33: =D60*1.09 -> 45.914375 | M33: =AVERAGE(J33:L33) -> 45.794397 | N33: =STDEV(J33:L33) -> 0.15871596 | O33: =N33/M33*100 -> 0.34658379 | P33: =(M33-I33)/I33*100 -> #DIV/0!
A34: BF CS 0102_1 | B34: Unknown | D34: =(E34+0.000638)/0.001817 -> 159.78976 | E34: 0.2897 | H34: CS 02-01 | J34: =D61*1.09 -> 57.072328 | K34: =D62*1.09 -> 56.652405 | L34: =D63*1.09 -> 56.292471 | M34: =AVERAGE(J34:L34) -> 56.672401 | N34: =STDEV(J34:L34) -> 0.39031281 | O34: =N34/M34*100 -> 0.68871761 | P34: =(M34-I34)/I34*100 -> #DIV/0!
A35: BF CS 0102_2 | B35: Unknown | D35: =(E35+0.000638)/0.001817 -> 160.34012 | E35: 0.2907 | H35: CS 02-02 | J35: =D64*1.09 -> 56.532427 | K35: =D65*1.09 -> 56.892361 | L35: =D66*1.09 -> 56.532427 | M35: =AVERAGE(J35:L35) -> 56.652405 | N35: =STDEV(J35:L35) -> 0.20780797 | O35: =N35/M35*100 -> 0.36681226 | P35: =(M35-I35)/I35*100 -> #DIV/0!
A36: BF CS 0102_3 | B36: Unknown | D36: =(E36+0.000638)/0.001817 -> 160.00991 | E36: 0.2901 | H36: CS 03-01 | J36: =D67*1.09 -> 52.153231 | K36: =D68*1.09 -> 52.393187 | L36: =D69*1.09 -> 52.093242 | M36: =AVERAGE(J36:L36) -> 52.21322 | N36: =STDEV(J36:L36) -> 0.15871596 | O36: =N36/M36*100 -> 0.30397657 | P36: =(M36-I36)/I36*100 -> #DIV/0!
A37: BF CS 0201_1 | B37: Unknown | D37: =(E37+0.000638)/0.001817 -> 239.81178 | E37: 0.4351 | H37: CS 03-02 | J37: =D70*1.09 -> 52.633143 | K37: =D71*1.09 -> 52.993076 | L37: =D72*1.09 -> 52.573154 | M37: =AVERAGE(J37:L37) -> 52.733124 | N37: =STDEV(J37:L37) -> 0.22711466 | O37: =N37/M37*100 -> 0.43068691 | P37: =(M37-I37)/I37*100 -> #DIV/0!
A38: BF CS 0201_2 | B38: Unknown | D38: =(E38+0.000638)/0.001817 -> 240.85746 | E38: 0.437 | G38: LDL Control | H38: CFS 21-01 | I38: 120.55077 | J38: =J22-J30 -> 120.26669 | K38: =K22-K30 -> 122.2832 | L38: =L22-L30 -> 122.13296 | M38: =AVERAGE(J38:L38) -> 121.56095 | N38: =STDEV(J38:L38) -> 1.123375 | O38: =N38/M38*100 -> 0.92412485 | P38: =(M38-I38)/I38*100 -> 0.83796991
A39: BF CS 0201_3 | B39: Unknown | D39: =(E39+0.000638)/0.001817 -> 239.81178 | E39: 0.4351 | H39: Q2 | I39: 137.9 | J39: =J23-J31 -> 140.84292 | K39: =K23-K31 -> 141.20285 | L39: =L23-L31 -> 140.5028 | M39: =AVERAGE(J39:L39) -> 140.84952 | N39: =STDEV(J39:L39) -> 0.35007424 | O39: =N39/M39*100 -> 0.24854486 | P39: =(M39-I39)/I39*100 -> 2.1388841
A40: BF CS 0202_1 | B40: Unknown | D40: =(E40+0.000638)/0.001817 -> 240.3071 | E40: 0.436 | G40: LDL | H40: CS 01-01 | J40: =J24-J32 -> 113.58535 | K40: =K24-K32 -> 113.96069 | L40: =L24-L32 -> 113.07021 | M40: =AVERAGE(J40:L40) -> 113.53875 | N40: =STDEV(J40:L40) -> 0.44706441 | O40: =N40/M40*100 -> 0.39375491 | P40: =(M40-I40)/I40*100 -> #DIV/0!
A41: BF CS 0202_2 | B41: Unknown | D41: =(E41+0.000638)/0.001817 -> 239.70171 | E41: 0.4349 | H41: CS 01-02 | J41: =J25-J33 -> 114.17533 | K41: =K25-K33 -> 114.48573 | L41: =L25-L33 -> 114.09553 | M41: =AVERAGE(J41:L41) -> 114.2522 | N41: =STDEV(J41:L41) -> 0.20614577 | O41: =N41/M41*100 -> 0.18043046 | P41: =(M41-I41)/I41*100 -> #DIV/0!
...

Sheet RESULT(Conc)_DAY2
D2: CON | E2: ABS
A3: B1 | B3: Standard | D3: 0 | E3: -0.0001 | F3: =(E3+0.001432)/0.001827 -> 0.72906404 | G3: =(E3+0.001084)/0.001825 -> 0.53917808 | H3: =D3-G3 -> -0.53917808 | I3: =(E3+0.001037)/0.001823 -> 0.51398793 | J3: =D3-K3 -> -0.63391877 | K3: =(E3+0.001255)/0.001822 -> 0.63391877
A4: B2 | B4: Standard | D4: 0 | E4: -0.0003 | F4: =(E4+0.001432)/0.001827 -> 0.61959496 | G4: =(E4+0.001084)/0.001825 -> 0.42958904 | H4: =D4-G4 -> -0.42958904 | I4: =(E4+0.001037)/0.001823 -> 0.40427866 | J4: =D4-K4 -> -0.52414929 | K4: =(E4+0.001255)/0.001822 -> 0.52414929
A5: 25_1 | B5: Standard | D5: 26.59 | E5: 0.0459 | F5: =(E5+0.001432)/0.001827 -> 25.906951 | G5: =(E5+0.001084)/0.001825 -> 25.744658 | H5: =D5-G5 -> 0.84534247 | I5: =(E5+0.001037)/0.001823 -> 25.74712 | J5: =D5-K5 -> 0.70909989 | K5: =(E5+0.001255)/0.001822 -> 25.8809
A6: 25_2 | B6: Standard | D6: 26.59 | F6: =(E6+0.001432)/0.001827 -> 0.78379858 | G6: =(E6+0.001084)/0.001825 -> 0.5939726 | H6: =D6-G6 -> 25.996027 | I6: =(E6+0.001037)/0.001823 -> 0.56884257 | J6: =D6-K6 -> 25.901196 | K6: =(E6+0.001255)/0.001822 -> 0.68880351
A7: 50_1 | B7: Standard | D7: 53 | F7: =(E7+0.001432)/0.001827 -> 0.78379858 | G7: =(E7+0.001084)/0.001825 -> 0.5939726 | H7: =D7-G7 -> 52.406027 | I7: =(E7+0.001037)/0.001823 -> 0.56884257 | J7: =D7-K7 -> 52.311196 | K7: =(E7+0.001255)/0.001822 -> 0.68880351
A8: 50_2 | B8: Standard | D8: 53 | E8: 0.0947 | F8: =(E8+0.001432)/0.001827 -> 52.617406 | G8: =(E8+0.001084)/0.001825 -> 52.484384 | H8: =D8-G8 -> 0.51561644 | I8: =(E8+0.001037)/0.001823 -> 52.516182 | J8: =D8-K8 -> 0.33534577 | K8: =(E8+0.001255)/0.001822 -> 52.664654
A9: 100_1 | B9: Standard | D9: 106.08 | E9: 0.1918 | F9: =(E9+0.001432)/0.001827 -> 105.76464 | G9: =(E9+0.001084)/0.001825 -> 105.68986 | H9: =D9-G9 -> 0.39013699 | I9: =(E9+0.001037)/0.001823 -> 105.78003 | J9: =D9-K9 -> 0.12226125 | K9: =(E9+0.001255)/0.001822 -> 105.95774
A10: 100_2 | B10: Standard | D10: 106.08 | E10: 0.1917 | F10: =(E10+0.001432)/0.001827 -> 105.70991 | G10: =(E10+0.001084)/0.001825 -> 105.63507 | H10: =D10-G10 -> 0.44493151 | I10: =(E10+0.001037)/0.001823 -> 105.72518 | J10: =D10-K10 -> 0.17714599 | K10: =(E10+0.001255)/0.001822 -> 105.90285
A11: 200_1 | B11: Standard | D11: 212.8 | F11: =(E11+0.001432)/0.001827 -> 0.78379858 | G11: =(E11+0.001084)/0.001825 -> 0.5939726 | H11: =D11-G11 -> 212.20603 | I11: =(E11+0.001037)/0.001823 -> 0.56884257 | J11: =D11-K11 -> 212.1112 | K11: =(E11+0.001255)/0.001822 -> 0.68880351
A12: 200_2 | B12: Standard | D12: 212.8 | F12: =(E12+0.001432)/0.001827 -> 0.78379858 | G12: =(E12+0.001084)/0.001825 -> 0.5939726 | H12: =D12-G12 -> 212.20603 | I12: =(E12+0.001037)/0.001823 -> 0.56884257 | J12: =D12-K12 -> 212.1112 | K12: =(E12+0.001255)/0.001822 -> 0.68880351
A13: 300_1 | B13: Standard | D13: 319.43 | E13: 0.5806 | F13: =(E13+0.001432)/0.001827 -> 318.57252 | G13: =(E13+0.001084)/0.001825 -> 318.73096 | H13: =D13-G13 -> 0.6990411 | I13: =(E13+0.001037)/0.001823 -> 319.05485 | J13: =D13-K13 -> 0.080384193 | K13: =(E13+0.001255)/0.001822 -> 319.34962
A14: 300_2 | B14: Standard | D14: 319.43 | F14: =(E14+0.001432)/0.001827 -> 0.78379858 | G14: =(E14+0.001084)/0.001825 -> 0.5939726 | H14: =D14-G14 -> 318.83603 | I14: =(E14+0.001037)/0.001823 -> 0.56884257 | J14: =D14-K14 -> 318.7412 | K14: =(E14+0.001255)/0.001822 -> 0.68880351
A15: 400_1 | B15: Standard | D15: 427.25 | E15: 0.7774 | F15: =(E15+0.001432)/0.001827 -> 426.29009 | G15: =(E15+0.001084)/0.001825 -> 426.56658 | H15: =D15-G15 -> 0.68342466 | I15: =(E15+0.001037)/0.001823 -> 427.00878 | J15: =D15-K15 -> -0.11278814 | K15: =(E15+0.001255)/0.001822 -> 427.36279
A16: 400_2 | B16: Standard | D16: 427.25 | F16: =(E16+0.001432)/0.001827 -> 0.78379858 | G16: =(E16+0.001084)/0.001825 -> 0.5939726 | H16: =D16-G16 -> 426.65603 | I16: =(E16+0.001037)/0.001823 -> 0.56884257 | J16: =D16-K16 -> 426.5612 | K16: =(E16+0.001255)/0.001822 -> 0.68880351
I17: STANDARD 제조일: 2025-10-22 | M17: * 실험일 : 2026-06-24 *실험담당 : 이현애
M18: * Abs 측정장비 :Shimadzu UV-2700
A19: NIST2_1 | B19: Unknown | D19: =(E19+0.001255)/0.001822 -> 244.92591 | E19: 0.445 | I19: A.value | J19: R1 | K19: R2 | L19: R3 | M19: mean | N19: stdev | O19: cv | P19: bias
A20: NIST2_2 | B20: Unknown | D20: =(E20+0.001255)/0.001822 -> 245.85895 | E20: 0.4467 | G20: QC | H20: NIST2 | I20: 244.8 | J20: =D19 -> 244.92591 | K20: =D20 -> 245.85895 | L20: =D21 -> 245.80406 | M20: =AVERAGE(J20:L20) -> 245.52964 | N20: =STDEV(J20:L20) -> 0.52356707 | O20: =N20/M20*100 -> 0.21323987 | P20: =(M20-I20)/I20*100 -> 0.29805464
A21: NIST2_3 | B21: Unknown | D21: =(E21+0.001255)/0.001822 -> 245.80406 | E21: 0.4466
D22: =(E22+0.001255)/0.001822 -> 0.68880351 | G22: BF Control | H22: CFS 21-01 | I22: 169.55748 | J22: =D25 -> 170.118 | K22: =D26 -> 171.9292 | L22: =D27 -> 170.77662 | M22: =AVERAGE(J22:L22) -> 170.94127 | N22: =STDEV(J22:L22) -> 0.91675593 | O22: =N22/M22*100 -> 0.53629876 | P22: =(M22-I22)/I22*100 -> 0.8161204
D23: =(E23+0.001255)/0.001822 -> 0.68880351
D24: =(E24+0.001255)/0.001822 -> 0.68880351 | G24: BF Sample | H24: CS 01-01 | J24: =D31 -> 160.4034 | K24: =D32 -> 160.73271 | L24: =D33 -> 160.56806 | M24: =AVERAGE(J24:L24) -> 160.56806 | N24: =STDEV(J24:L24) -> 0.16465423 | O24: =N24/M24*100 -> 0.10254482 | P24: =(M24-I24)/I24*100 -> #DIV/0!
A25: BF CFS2101_1 | B25: Unknown | D25: =(E25+0.001255)/0.001822 -> 170.118 | E25: 0.3087 | H25: CS 01-02 | J25: =D34 -> 161.17179 | K25: =D35 -> 160.7876 | L25: =D36 -> 159.74479 | M25: =AVERAGE(J25:L25) -> 160.56806 | N25: =STDEV(J25:L25) -> 0.73839869 | O25: =N25/M25*100 -> 0.45986649 | P25: =(M25-I25)/I25*100 -> #DIV/0!
A26: BF CFS2101_2 | B26: Unknown | D26: =(E26+0.001255)/0.001822 -> 171.9292 | E26: 0.312 | H26: CS 02-01 | J26: =D37 -> 240.42536 | K26: =D38 -> 240.37047 | L26: =D39 -> 240.59001 | M26: =AVERAGE(J26:L26) -> 240.46195 | N26: =STDEV(J26:L26) -> 0.1142517 | O26: =N26/M26*100 -> 0.047513423 | P26: =(M26-I26)/I26*100 -> #DIV/0!
A27: BF CFS2101_3 | B27: Unknown | D27: =(E27+0.001255)/0.001822 -> 170.77662 | E27: 0.3099 | H27: CS 02-02 | J27: =D40 -> 241.63282 | K27: =D41 -> 241.08397 | L27: =D42 -> 242.7854 | M27: =AVERAGE(J27:L27) -> 241.83407 | N27: =STDEV(J27:L27) -> 0.86838231 | O27: =N27/M27*100 -> 0.35908188 | P27: =(M27-I27)/I27*100 -> #DIV/0!
A28: BF QAS CNU 1703_1 | B28: Unknown | D28: =(E28+0.001255)/0.001822 -> 152.77442 | E28: 0.2771 | H28: CS 03-01 | J28: =D43 -> 131.14984 | K28: =D44 -> 131.2596 | L28: =D45 -> 131.69868 | M28: =AVERAGE(J28:L28) -> 131.36937 | N28: =STDEV(J28:L28) -> 0.29042276 | O28: =N28/M28*100 -> 0.22107341 | P28: =(M28-I28)/I28*100 -> #DIV/0!
A29: BF QAS CNU 1703_2 | B29: Unknown | D29: =(E29+0.001255)/0.001822 -> 152.55488 | E29: 0.2767 | H29: CS 03-02 | J29: =D46 -> 132.30241 | K29: =D47 -> 132.19265 | L29: =D48 -> 132.74149 | M29: =AVERAGE(J29:L29) -> 132.41218 | N29: =STDEV(J29:L29) -> 0.29042276 | O29: =N29/M29*100 -> 0.21933235 | P29: =(M29-I29)/I29*100 -> #DIV/0!
A30: BF QAS CNU 1703_3 | B30: Unknown | D30: =(E30+0.001255)/0.001822 -> 154.09166 | E30: 0.2795 | G30: HDL Control x1.09 | H30: CFS 21-01 | I30: 49.006709 | J30: =D49*1.09 -> 49.627305 | K30: =D50*1.09 -> 49.208535 | L30: =D51*1.09 -> 49.567481 | M30: =AVERAGE(J30:L30) -> 49.467774 | N30: =STDEV(J30:L30) -> 0.2264914 | O30: =N30/M30*100 -> 0.45785648 | P30: =(M30-I30)/I30*100 -> 0.94081906
A31: BF CS 0101_1 | B31: Unknown | D31: =(E31+0.001255)/0.001822 -> 160.4034 | E31: 0.291
A32: BF CS 0101_2 | B32: Unknown | D32: =(E32+0.001255)/0.001822 -> 160.73271 | E32: 0.2916 | G32: HDL Sample x1.09 | H32: CS 01-01 | J32: =D55*1.09 -> 47.174506 | K32: =D56*1.09 -> 46.097667 | L32: =D57*1.09 -> 46.935209 | M32: =AVERAGE(J32:L32) -> 46.735794 | N32: =STDEV(J32:L32) -> 0.56543787 | O32: =N32/M32*100 -> 1.2098604 | P32: =(M32-I32)/I32*100 -> #DIV/0!
A33: BF CS 0101_3 | B33: Unknown | D33: =(E33+0.001255)/0.001822 -> 160.56806 | E33: 0.2913 | H33: CS 01-02 | J33: =D58*1.09 -> 46.396789 | K33: =D59*1.09 -> 46.636087 | L33: =D60*1.09 -> 46.695911 | M33: =AVERAGE(J33:L33) -> 46.576262 | N33: =STDEV(J33:L33) -> 0.1582804 | O33: =N33/M33*100 -> 0.33983062 | P33: =(M33-I33)/I33*100 -> #DIV/0!
A34: BF CS 0102_1 | B34: Unknown | D34: =(E34+0.001255)/0.001822 -> 161.17179 | E34: 0.2924 | H34: CS 02-01 | J34: =D61*1.09 -> 57.165176 | K34: =D62*1.09 -> 56.985703 | L34: =D63*1.09 -> 57.165176 | M34: =AVERAGE(J34:L34) -> 57.105351 | N34: =STDEV(J34:L34) -> 0.10361885 | O34: =N34/M34*100 -> 0.18145208 | P34: =(M34-I34)/I34*100 -> #DIV/0!
A35: BF CS 0102_2 | B35: Unknown | D35: =(E35+0.001255)/0.001822 -> 160.7876 | E35: 0.2917 | H35: CS 02-02 | J35: =D64*1.09 -> 57.284824 | K35: =D65*1.09 -> 57.643771 | L35: =D66*1.09 -> 56.985703 | M35: =AVERAGE(J35:L35) -> 57.304766 | N35: =STDEV(J35:L35) -> 0.32948693 | O35: =N35/M35*100 -> 0.574973 | P35: =(M35-I35)/I35*100 -> #DIV/0!
A36: BF CS 0102_3 | B36: Unknown | D36: =(E36+0.001255)/0.001822 -> 159.74479 | E36: 0.2898 | H36: CS 03-01 | J36: =D67*1.09 -> 52.917645 | K36: =D68*1.09 -> 52.498875 | L36: =D69*1.09 -> 52.498875 | M36: =AVERAGE(J36:L36) -> 52.638465 | N36: =STDEV(J36:L36) -> 0.24177731 | O36: =N36/M36*100 -> 0.45931679 | P36: =(M36-I36)/I36*100 -> #DIV/0!
A37: BF CS 0201_1 | B37: Unknown | D37: =(E37+0.001255)/0.001822 -> 240.42536 | E37: 0.4368 | H37: CS 03-02 | J37: =D70*1.09 -> 52.857821 | K37: =D71*1.09 -> 52.857821 | L37: =D72*1.09 -> 52.917645 | M37: =AVERAGE(J37:L37) -> 52.877763 | N37: =STDEV(J37:L37) -> 0.034539615 | O37: =N37/M37*100 -> 0.065319737 | P37: =(M37-I37)/I37*100 -> #DIV/0!
A38: BF CS 0201_2 | B38: Unknown | D38: =(E38+0.001255)/0.001822 -> 240.37047 | E38: 0.4367 | G38: LDL Control | H38: CFS 21-01 | I38: 120.55077 | J38: =J22-J30 -> 120.4907 | K38: =K22-K30 -> 122.72066 | L38: =L22-L30 -> 121.20914 | M38: =AVERAGE(J38:L38) -> 121.4735 | N38: =STDEV(J38:L38) -> 1.1382458 | O38: =N38/M38*100 -> 0.93703221 | P38: =(M38-I38)/I38*100 -> 0.76542747
A39: BF CS 0201_3 | B39: Unknown | D39: =(E39+0.001255)/0.001822 -> 240.59001 | E39: 0.4371
A40: BF CS 0202_1 | B40: Unknown | D40: =(E40+0.001255)/0.001822 -> 241.63282 | E40: 0.439 | G40: LDL | H40: CS 01-01 | J40: =J24-J32 -> 113.2289 | K40: =K24-K32 -> 114.63504 | L40: =L24-L32 -> 113.63285 | M40: =AVERAGE(J40:L40) -> 113.83226 | N40: =STDEV(J40:L40) -> 0.72397309 | O40: =N40/M40*100 -> 0.63599991 | P40: =(M40-I40)/I40*100 -> #DIV/0!
A41: BF CS 0202_2 | B41: Unknown | D41: =(E41+0.001255)/0.001822 -> 241.08397 | E41: 0.438 | H41: CS 01-02 | J41: =J25-J33 -> 114.775 | K41: =K25-K33 -> 114.15151 | L41: =L25-L33 -> 113.04887 | M41: =AVERAGE(J41:L41) -> 113.99179 | N41: =STDEV(J41:L41) -> 0.87407583 | O41: =N41/M41*100 -> 0.76678838 | P41: =(M41-I41)/I41*100 -> #DIV/0!
...

Sheet 2026-07_결과정리
B2: DAY 1 | D2: STANDARD 제조일: 2025-10-22 | H2: * 실험일 : 2026-06-18 *실험담당 : 이현애 | N2: DAY 2 | P2: STANDARD 제조일: 2025-10-22 | T2: * 실험일 : 2026-06-24 *실험담당 : 이현애
H3: * Abs 측정장비 :Shimadzu UV-2700 | T3: * Abs 측정장비 :Shimadzu UV-2700
D4: A.value | E4: R1 | F4: R2 | G4: R3 | H4: mean | I4: stdev | J4: cv | K4: bias(%) | L4: bias(mg/dl) | P4: A.value | Q4: R1 | R4: R2 | S4: R3 | T4: mean | U4: stdev | V4: cv | W4: bias(%) | X4: bias(mg/dl)
B5: QC | C5: NIST1 | D5: 154.6 | E5: 154.45129 | F5: 154.45129 | G5: 155.66208 | H5: =AVERAGE(E5:G5) -> 154.85489 | I5: =STDEV(E5:G5) -> 0.69904821 | J5: =I5/H5*100 -> 0.45142146 | K5: =(H5-D5)/D5*100 -> 0.16486999 | N5: QC | O5: NIST2 | P5: 244.8 | Q5: 244.92591 | R5: 245.85895 | S5: 245.80406 | T5: =AVERAGE(Q5:S5) -> 245.52964 | U5: =STDEV(Q5:S5) -> 0.52356707 | V5: =U5/T5*100 -> 0.21323987 | W5: =(T5-P5)/P5*100 -> 0.29805464
B7: BF Control | C7: CFS 21-01 | D7: 169.55748 | E7: 168.76059 | F7: 171.01706 | G7: 170.68685 | H7: =AVERAGE(E7:G7) -> 170.15483 | I7: =STDEV(E7:G7) -> 1.2186831 | J7: =I7/H7*100 -> 0.71622008 | K7: =(H7-D7)/D7*100 -> 0.35230167 | L7: =H7-D7 -> 0.59735383 | N7: BF Control | O7: CFS 21-01 | P7: 169.55748 | Q7: 170.118 | R7: 171.9292 | S7: 170.77662 | T7: =AVERAGE(Q7:S7) -> 170.94127 | U7: =STDEV(Q7:S7) -> 0.91675593 | V7: =U7/T7*100 -> 0.53629876 | W7: =(T7-P7)/P7*100 -> 0.8161204 | X7: =T7-P7 -> 1.3837932
C8: Q2 | D8: 196.2 | E8: 198.75509 | F8: 198.75509 | G8: 198.53495 | H8: =AVERAGE(E8:G8) -> 198.68171 | I8: =STDEV(E8:G8) -> 0.12709967 | J8: =I8/H8*100 -> 0.063971502 | K8: =(H8-D8)/D8*100 -> 1.2648878 | L8: =H8-D8 -> 2.4817098
B9: BF Sample | C9: CS 01-01 | E9: 159.67969 | F9: 160.17501 | G9: 159.40451 | H9: =AVERAGE(E9:G9) -> 159.75307 | I9: =STDEV(E9:G9) -> 0.39045674 | J9: =I9/H9*100 -> 0.24441266 | K9: =(H9-D9)/D9*100 -> #DIV/0! | N9: BF Sample | O9: CS 01-01 | Q9: 160.4034 | R9: 160.73271 | S9: 160.56806 | T9: =AVERAGE(Q9:S9) -> 160.56806 | U9: =STDEV(Q9:S9) -> 0.16465423 | V9: =U9/T9*100 -> 0.10254482 | W9: =(T9-P9)/P9*100 -> #DIV/0!
C10: CS 01-02 | E10: 159.78976 | F10: 160.34012 | G10: 160.00991 | H10: =AVERAGE(E10:G10) -> 160.0466 | I10: =STDEV(E10:G10) -> 0.27700732 | J10: =I10/H10*100 -> 0.17307917 | K10: =(H10-D10)/D10*100 -> #DIV/0! | O10: CS 01-02 | Q10: 161.17179 | R10: 160.7876 | S10: 159.74479 | T10: =AVERAGE(Q10:S10) -> 160.56806 | U10: =STDEV(Q10:S10) -> 0.73839869 | V10: =U10/T10*100 -> 0.45986649 | W10: =(T10-P10)/P10*100 -> #DIV/0!
C11: CS 02-01 | E11: 239.81178 | F11: 240.85746 | G11: 239.81178 | H11: =AVERAGE(E11:G11) -> 240.16034 | I11: =STDEV(E11:G11) -> 0.60372345 | J11: =I11/H11*100 -> 0.2513835 | K11: =(H11-D11)/D11*100 -> #DIV/0! | O11: CS 02-01 | Q11: 240.42536 | R11: 240.37047 | S11: 240.59001 | T11: =AVERAGE(Q11:S11) -> 240.46195 | U11: =STDEV(Q11:S11) -> 0.1142517 | V11: =U11/T11*100 -> 0.047513423 | W11: =(T11-P11)/P11*100 -> #DIV/0!
C12: CS 02-02 | E12: 240.3071 | F12: 239.70171 | G12: 240.52724 | H12: =AVERAGE(E12:G12) -> 240.17868 | I12: =STDEV(E12:G12) -> 0.42748781 | J12: =I12/H12*100 -> 0.17798741 | K12: =(H12-D12)/D12*100 -> #DIV/0! | O12: CS 02-02 | Q12: 241.63282 | R12: 241.08397 | S12: 242.7854 | T12: =AVERAGE(Q12:S12) -> 241.83407 | U12: =STDEV(Q12:S12) -> 0.86838231 | V12: =U12/T12*100 -> 0.35908188 | W12: =(T12-P12)/P12*100 -> #DIV/0!
C13: CS 03-01 | E13: 132.7672 | F13: 132.49202 | G13: 132.49202 | H13: =AVERAGE(E13:G13) -> 132.58375 | I13: =STDEV(E13:G13) -> 0.15887459 | J13: =I13/H13*100 -> 0.11982962 | K13: =(H13-D13)/D13*100 -> #DIV/0! | O13: CS 03-01 | Q13: 131.14984 | R13: 131.2596 | S13: 131.69868 | T13: =AVERAGE(Q13:S13) -> 131.36937 | U13: =STDEV(Q13:S13) -> 0.29042276 | V13: =U13/T13*100 -> 0.22107341 | W13: =(T13-P13)/P13*100 -> #DIV/0!
C14: CS 03-02 | E14: 131.83159 | F14: 132.32691 | G14: 132.43698 | H14: =AVERAGE(E14:G14) -> 132.1985 | I14: =STDEV(E14:G14) -> 0.3224802 | J14: =I14/H14*100 -> 0.24393636 | K14: =(H14-D14)/D14*100 -> #DIV/0! | O14: CS 03-02 | Q14: 132.30241 | R14: 132.19265 | S14: 132.74149 | T14: =AVERAGE(Q14:S14) -> 132.41218 | U14: =STDEV(Q14:S14) -> 0.29042276 | V14: =U14/T14*100 -> 0.21933235 | W14: =(T14-P14)/P14*100 -> #DIV/0!
B15: HDL Control x1.09 | C15: CFS 21-01 | D15: 49.006709 | E15: 48.493902 | F15: 48.733858 | G15: 48.553891 | H15: =AVERAGE(E15:G15) -> 48.593884 | I15: =STDEV(E15:G15) -> 0.12487705 | J15: =I15/H15*100 -> 0.256981 | K15: =(H15-D15)/D15*100 -> -0.84238539 | L15: =H15-D15 -> -0.41282536 | N15: HDL Control x1.09 | O15: CFS 21-01 | P15: 49.006709 | Q15: 49.627305 | R15: 49.208535 | S15: 49.567481 | T15: =AVERAGE(Q15:S15) -> 49.467774 | U15: =STDEV(Q15:S15) -> 0.2264914 | V15: =U15/T15*100 -> 0.45785648 | W15: =(T15-P15)/P15*100 -> 0.94081906 | X15: =T15-P15 -> 0.46106446
C16: Q2 | D16: 58.3 | E16: 57.912174 | F16: 57.55224 | G16: 58.032152 | H16: =AVERAGE(E16:G16) -> 57.832189 | I16: =STDEV(E16:G16) -> 0.24975409 | J16: =I16/H16*100 -> 0.43186001 | K16: =(H16-D16)/D16*100 -> -0.80242094 | L16: =H16-D16 -> -0.46781141
B17: HDL Sample x1.09 | C17: CS 01-01 | E17: 46.094342 | F17: 46.21432 | G17: 46.334298 | H17: =AVERAGE(E17:G17) -> 46.21432 | I17: =STDEV(E17:G17) -> 0.11997799 | J17: =I17/H17*100 -> 0.25961214 | K17: =(H17-D17)/D17*100 -> #DIV/0! | N17: HDL Sample x1.09 | O17: CS 01-01 | Q17: 47.174506 | R17: 46.097667 | S17: 46.935209 | T17: =AVERAGE(Q17:S17) -> 46.735794 | U17: =STDEV(Q17:S17) -> 0.56543787 | V17: =U17/T17*100 -> 1.2098604 | W17: =(T17-P17)/P17*100 -> #DIV/0!
C18: CS 01-02 | E18: 45.61443 | F18: 45.854386 | G18: 45.914375 | H18: =AVERAGE(E18:G18) -> 45.794397 | I18: =STDEV(E18:G18) -> 0.15871596 | J18: =I18/H18*100 -> 0.34658379 | K18: =(H18-D18)/D18*100 -> #DIV/0! | O18: CS 01-02 | Q18: 46.396789 | R18: 46.636087 | S18: 46.695911 | T18: =AVERAGE(Q18:S18) -> 46.576262 | U18: =STDEV(Q18:S18) -> 0.1582804 | V18: =U18/T18*100 -> 0.33983062 | W18: =(T18-P18)/P18*100 -> #DIV/0!
C19: CS 02-01 | E19: 57.072328 | F19: 56.652405 | G19: 56.292471 | H19: =AVERAGE(E19:G19) -> 56.672401 | I19: =STDEV(E19:G19) -> 0.39031281 | J19: =I19/H19*100 -> 0.68871761 | K19: =(H19-D19)/D19*100 -> #DIV/0! | O19: CS 02-01 | Q19: 57.165176 | R19: 56.985703 | S19: 57.165176 | T19: =AVERAGE(Q19:S19) -> 57.105351 | U19: =STDEV(Q19:S19) -> 0.10361885 | V19: =U19/T19*100 -> 0.18145208 | W19: =(T19-P19)/P19*100 -> #DIV/0!
C20: CS 02-02 | E20: 56.532427 | F20: 56.892361 | G20: 56.532427 | H20: =AVERAGE(E20:G20) -> 56.652405 | I20: =STDEV(E20:G20) -> 0.20780797 | J20: =I20/H20*100 -> 0.36681226 | K20: =(H20-D20)/D20*100 -> #DIV/0! | O20: CS 02-02 | Q20: 57.284824 | R20: 57.643771 | S20: 56.985703 | T20: =AVERAGE(Q20:S20) -> 57.304766 | U20: =STDEV(Q20:S20) -> 0.32948693 | V20: =U20/T20*100 -> 0.574973 | W20: =(T20-P20)/P20*100 -> #DIV/0!
C21: CS 03-01 | E21: 52.153231 | F21: 52.393187 | G21: 52.093242 | H21: =AVERAGE(E21:G21) -> 52.21322 | I21: =STDEV(E21:G21) -> 0.15871596 | J21: =I21/H21*100 -> 0.30397657 | K21: =(H21-D21)/D21*100 -> #DIV/0! | O21: CS 03-01 | Q21: 52.917645 | R21: 52.498875 | S21: 52.498875 | T21: =AVERAGE(Q21:S21) -> 52.638465 | U21: =STDEV(Q21:S21) -> 0.24177731 | V21: =U21/T21*100 -> 0.45931679 | W21: =(T21-P21)/P21*100 -> #DIV/0!
C22: CS 03-02 | E22: 52.633143 | F22: 52.993076 | G22: 52.573154 | H22: =AVERAGE(E22:G22) -> 52.733124 | I22: =STDEV(E22:G22) -> 0.22711466 | J22: =I22/H22*100 -> 0.43068691 | K22: =(H22-D22)/D22*100 -> #DIV/0! | O22: CS 03-02 | Q22: 52.857821 | R22: 52.857821 | S22: 52.917645 | T22: =AVERAGE(Q22:S22) -> 52.877763 | U22: =STDEV(Q22:S22) -> 0.034539615 | V22: =U22/T22*100 -> 0.065319737 | W22: =(T22-P22)/P22*100 -> #DIV/0!
B23: LDL Control | C23: CFS 21-01 | D23: 120.55077 | E23: 120.26669 | F23: 122.2832 | G23: 122.13296 | H23: =AVERAGE(E23:G23) -> 121.56095 | I23: =STDEV(E23:G23) -> 1.123375 | J23: =I23/H23*100 -> 0.92412485 | K23: =(H23-D23)/D23*100 -> 0.83796991 | L23: =H23-D23 -> 1.0101792 | N23: LDL Control | O23: CFS 21-01 | P23: 120.55077 | Q23: 120.4907 | R23: 122.72066 | S23: 121.20914 | T23: =AVERAGE(Q23:S23) -> 121.4735 | U23: =STDEV(Q23:S23) -> 1.1382458 | V23: =U23/T23*100 -> 0.93703221 | W23: =(T23-P23)/P23*100 -> 0.76542747 | X23: =T23-P23 -> 0.92272872
C24: Q2 | D24: 137.9 | E24: 140.84292 | F24: 141.20285 | G24: 140.5028 | H24: =AVERAGE(E24:G24) -> 140.84952 | I24: =STDEV(E24:G24) -> 0.35007424 | J24: =I24/H24*100 -> 0.24854486 | K24: =(H24-D24)/D24*100 -> 2.1388841 | L24: =H24-D24 -> 2.9495212
B25: LDL | C25: CS 01-01 | E25: 113.58535 | F25: 113.96069 | G25: 113.07021 | H25: =AVERAGE(E25:G25) -> 113.53875 | I25: =STDEV(E25:G25) -> 0.44706441 | J25: =I25/H25*100 -> 0.39375491 | K25: =(H25-D25)/D25*100 -> #DIV/0! | N25: LDL | O25: CS 01-01 | Q25: 113.2289 | R25: 114.63504 | S25: 113.63285 | T25: =AVERAGE(Q25:S25) -> 113.83226 | U25: =STDEV(Q25:S25) -> 0.72397309 | V25: =U25/T25*100 -> 0.63599991 | W25: =(T25-P25)/P25*100 -> #DIV/0!
C26: CS 01-02 | E26: 114.17533 | F26: 114.48573 | G26: 114.09553 | H26: =AVERAGE(E26:G26) -> 114.2522 | I26: =STDEV(E26:G26) -> 0.20614577 | J26: =I26/H26*100 -> 0.18043046 | K26: =(H26-D26)/D26*100 -> #DIV/0! | O26: CS 01-02 | Q26: 114.775 | R26: 114.15151 | S26: 113.04887 | T26: =AVERAGE(Q26:S26) -> 113.99179 | U26: =STDEV(Q26:S26) -> 0.87407583 | V26: =U26/T26*100 -> 0.76678838 | W26: =(T26-P26)/P26*100 -> #DIV/0!
C27: CS 02-01 | E27: 182.73945 | F27: 184.20505 | G27: 183.51931 | H27: =AVERAGE(E27:G27) -> 183.48794 | I27: =STDEV(E27:G27) -> 0.73330475 | J27: =I27/H27*100 -> 0.39964739 | K27: =(H27-D27)/D27*100 -> #DIV/0! | O27: CS 02-01 | Q27: 183.26018 | R27: 183.38477 | S27: 183.42484 | T27: =AVERAGE(Q27:S27) -> 183.3566 | U27: =STDEV(Q27:S27) -> 0.085866707 | V27: =U27/T27*100 -> 0.046830444 | W27: =(T27-P27)/P27*100 -> #DIV/0!
C28: CS 02-02 | E28: 183.77467 | F28: 182.80935 | G28: 183.99482 | H28: =AVERAGE(E28:G28) -> 183.52628 | I28: =STDEV(E28:G28) -> 0.63056331 | J28: =I28/H28*100 -> 0.34358203 | K28: =(H28-D28)/D28*100 -> #DIV/0! | O28: CS 02-02 | Q28: 184.348 | R28: 183.4402 | S28: 185.7997 | T28: =AVERAGE(Q28:S28) -> 184.5293 | U28: =STDEV(Q28:S28) -> 1.1901501 | V28: =U28/T28*100 -> 0.64496537 | W28: =(T28-P28)/P28*100 -> #DIV/0!
C29: CS 03-01 | E29: 80.613968 | F29: 80.098833 | G29: 80.398778 | H29: =AVERAGE(E29:G29) -> 80.370527 | I29: =STDEV(E29:G29) -> 0.25872687 | J29: =I29/H29*100 -> 0.3219176 | K29: =(H29-D29)/D29*100 -> #DIV/0! | O29: CS 03-01 | Q29: 78.23219 | R29: 78.76073 | S29: 79.199808 | T29: =AVERAGE(Q29:S29) -> 78.730909 | U29: =STDEV(Q29:S29) -> 0.48449779 | V29: =U29/T29*100 -> 0.61538447 | W29: =(T29-P29)/P29*100 -> #DIV/0!
C30: CS 03-02 | E30: 79.198448 | F30: 79.333836 | G30: 79.86383 | H30: =AVERAGE(E30:G30) -> 79.465371 | I30: =STDEV(E30:G30) -> 0.35165275 | J30: =I30/H30*100 -> 0.44252326 | K30: =(H30-D30)/D30*100 -> #DIV/0! | O30: CS 03-02 | Q30: 79.444594 | R30: 79.334824 | S30: 79.823847 | T30: =AVERAGE(Q30:S30) -> 79.534422 | U30: =STDEV(Q30:S30) -> 0.25658857 | V30: =U30/T30*100 -> 0.32261323 | W30: =(T30-P30)/P30*100 -> #DIV/0!

Sheet 제출결과_선택검토
B1: CRMLN 제출 결과 선택 검토 (2026-07 회차)
B2: KDCA NMRL(Lab 509) · [2026-07_결과정리] 시트 양식 기준 · 채택 2반복 = 노란색 표시
AK3: 드롭다운 소스(대시보드 ③ 선택 옵션과 동일)
B4: 선택 옵션 | C4: HDL 높은값 우선 (상위 2개 채택) | AJ4: 정밀도 기준 (권장) | AK4: 종합 (BF+HDL 상대편차) · 균형 [기본]
B5: 옵션 설명 | C5: =IF($C$8="ALL","제외 없이 R1·R2·R3 전체 평균을 사용합니다(선택 미적용·비교 참고용).",IF($C$8="MAN","부록 ⑤ 표의 S열에 검체·Day별로 제외할 replicate(R1/R2/R3)를 직접 지정합니다.",IF($C$8="PAIR","BF·HDL·LDL 상대간격의 합이 가장 작은 2개(가장 근접한 쌍)를 채택합니다.",IF(LEFT($C$8,3)="DIR","방향성 what-if: "&$C$4&" — 정밀도가 아닌 값의 크기로 2개를 채택하므로 민감도 확인 전용입니다.","median 대비 상대편차(%)를 "&IF($C$4=$AK$4,"BF+HDL 합산",IF($C$4=$AK$5,"LDL",IF($C$4=$AK$6,"BF",IF($C$4=$AK$7,"HDL","BF+HDL+LDL 합산"))))&" 기준으로 계산해 편차가 가장 큰 replicate 1개를 제외합니다(BF·HDL·LDL 동일 R index 잠금).")))) -> 방향성 what-if: HDL 높은값 우선 (상위 2개 채택) — 정밀도가 아닌 값의 크기로 2개를 채택하므로 민감도 확인 전용입니다. | AK5: LDL 결과 우선 (LDL 편차 최소)
B6: 편차 가중치 | C6: =IF(OR($C$4=$AK$4,$C$4=$AK$6,$C$4=$AK$8),1,0) -> 0 | D6: =IF(OR($C$4=$AK$4,$C$4=$AK$7,$C$4=$AK$8),1,0) -> 0 | E6: =IF(OR($C$4=$AK$5,$C$4=$AK$8),1,0) -> 0 | F6: ← BF / HDL / LDL 가중치 (옵션에 따라 자동) | AK6: BF(하부분획) 우선
B7: 참고 | C7: 옵션을 바꾸면 아래 표의 채택 셀(노란색)·평균·판정이 즉시 재계산됩니다. QC·Control은 선택 대상이 아니며 3반복 전체를 사용합니다. | AK7: HDL 우선
B8: 적용 로직 | C8: =IF($C$4=$AK$9,"PAIR",IF($C$4=$AK$10,"DIR_HDL_HI",IF($C$4=$AK$11,"DIR_HDL_LO",IF($C$4=$AK$12,"DIR_BF_HI",IF($C$4=$AK$13,"DIR_BF_LO",IF($C$4=$AK$14,"ALL",IF($C$4=$AK$15,"MAN","SCORE"))))))) -> DIR_HDL_HI | D8: =IF($C$8="SCORE","median 대비 가중 상대편차 최대 replicate 1개 제외",IF($C$8="PAIR","잔여 2개의 상대간격 합이 최소가 되도록 1개 제외",IF($C$8="ALL","제외 없음(3반복 평균)",IF($C$8="MAN","부록 ⑤ S열 직접 입력","해당 항목 값의 크기 순으로 상위/하위 2개 채택")))) -> 해당 항목 값의 크기 순으로 상위/하위 2개 채택 | AK8: 3항목 종합 (BF+HDL+LDL)
C9: =IF(LEFT($C$8,3)="DIR","⚠ 방향성 옵션은 결과를 유리하게 만드는 선택이 아니며 민감도 분석 전용입니다. 제출은 정밀도 기준 옵션을 사용하세요.","") -> ⚠ 방향성 옵션은 결과를 유리하게 만드는 선택이 아니며 민감도 분석 전용입니다. 제출은 정밀도 기준 옵션을 사용하세요. | AK9: 최소분산 쌍 (가장 근접 2개 채택)
B10: ① 검체·Day별 선택 결과 (결과정리 시트 양식 · 채택 2반복 = 노란색) | AJ10: 방향성 (민감도·what-if) | AK10: HDL 높은값 우선 (상위 2개 채택)
AK11: HDL 낮은값 우선 (하위 2개 채택)
B12: ='2026-07_결과정리'!B2 -> DAY 1 | D12: ='2026-07_결과정리'!D2 -> STANDARD 제조일: 2025-10-22 | H12: ='2026-07_결과정리'!H2 -> * 실험일 : 2026-06-18 *실험담당 : 이현애 | R12: ='2026-07_결과정리'!N2 -> DAY 2 | T12: ='2026-07_결과정리'!P2 -> STANDARD 제조일: 2025-10-22 | X12: ='2026-07_결과정리'!T2 -> * 실험일 : 2026-06-24 *실험담당 : 이현애 | AK12: BF 높은값 우선 (상위 2개 채택)
H13: ='2026-07_결과정리'!H3 -> * Abs 측정장비 :Shimadzu UV-2700 | X13: ='2026-07_결과정리'!T3 -> * Abs 측정장비 :Shimadzu UV-2700 | AK13: BF 낮은값 우선 (하위 2개 채택)
B14: 구분 | C14: 검체 | D14: A.value | E14: R1 | F14: R2 | G14: R3 | H14: mean(채택) | I14: stdev | J14: cv | K14: bias(%) | L14: bias(mg/dl) | M14: 기본(종합) 채택 | N14: Δ 평균 (옵션−기본) | O14: 기본 CV% | P14: Δ CV%p (옵션−기본) | R14: 구분 | S14: 검체 | T14: A.value | U14: R1 | V14: R2 | W14: R3 | X14: mean(채택) | Y14: stdev | Z14: cv | AA14: bias(%) | AB14: bias(mg/dl) | AC14: 기본(종합) 채택 | AD14: Δ 평균 (옵션−기본) | AE14: 기본 CV% | AF14: Δ CV%p (옵션−기본) | AJ14: 기타(검토용) | AK14: 3반복 전체 (참고·선택 미적용) | AM14: 검체idx | AN14: D1 제외idx | AO14: D2 제외idx | AP14: D1 기본idx | AQ14: D2 기본idx
B15: =IF('2026-07_결과정리'!B5="","",'2026-07_결과정리'!B5) -> QC | C15: =IF('2026-07_결과정리'!C5="","",'2026-07_결과정리'!C5) -> NIST1 | D15: =IF('2026-07_결과정리'!D5="","",'2026-07_결과정리'!D5) -> 154.6 | E15: =IF('2026-07_결과정리'!E5="","",'2026-07_결과정리'!E5) -> 154.45129 | F15: =IF('2026-07_결과정리'!F5="","",'2026-07_결과정리'!F5) -> 154.45129 | G15: =IF('2026-07_결과정리'!G5="","",'2026-07_결과정리'!G5) -> 155.66208 | H15: {=IF($E15="","",IF($AN15=0,AVERAGE($E15:$G15),(SUM($E15:$G15)-INDEX($E15:$G15,$AN15))/2))} -> 154.85489 | I15: =IF($E15="","",IF($AN15=0,STDEV($E15:$G15),ABS(CHOOSE($AN15,$F15-$G15,$E15-$G15,$E15-$F15))/SQRT(2))) -> 0.69904821 | J15: =IF($H15="","",$I15/$H15*100) -> 0.45142146 | K15: =IF(OR($H15="",$D15=""),"",($H15-$D15)/$D15*100) -> 0.16486999 | M15: {=IF(OR($E15="",$AM15=0),"",(SUM($E15:$G15)-INDEX($E15:$G15,$AP15))/2)} | N15: =IF($M15="","",$H15-$M15) | O15: =IF($M15="","",ABS(CHOOSE($AP15,$F15-$G15,$E15-$G15,$E15-$F15))/SQRT(2)/$M15*100) | P15: =IF($O15="","",ROUND($J15-$O15,3)) | R15: =IF('2026-07_결과정리'!N5="","",'2026-07_결과정리'!N5) -> QC | S15: =IF('2026-07_결과정리'!O5="","",'2026-07_결과정리'!O5) -> NIST2 | T15: =IF('2026-07_결과정리'!P5="","",'2026-07_결과정리'!P5) -> 244.8 | U15: =IF('2026-07_결과정리'!Q5="","",'2026-07_결과정리'!Q5) -> 244.92591 | V15: =IF('2026-07_결과정리'!R5="","",'2026-07_결과정리'!R5) -> 245.85895 | W15: =IF('2026-07_결과정리'!S5="","",'2026-07_결과정리'!S5) -> 245.80406 | X15: {=IF($U15="","",IF($AO15=0,AVERAGE($U15:$W15),(SUM($U15:$W15)-INDEX($U15:$W15,$AO15))/2))} -> 245.52964 | Y15: =IF($U15="","",IF($AO15=0,STDEV($U15:$W15),ABS(CHOOSE($AO15,$V15-$W15,$U15-$W15,$U15-$V15))/SQRT(2))) -> 0.52356707 | Z15: =IF($X15="","",$Y15/$X15*100) -> 0.21323987 | AA15: =IF(OR($X15="",$T15=""),"",($X15-$T15)/$T15*100) -> 0.29805464 | AC15: {=IF(OR($U15="",$AM15=0),"",(SUM($U15:$W15)-INDEX($U15:$W15,$AQ15))/2)} | AD15: =IF($AC15="","",$X15-$AC15) | AE15: =IF($AC15="","",ABS(CHOOSE($AQ15,$V15-$W15,$U15-$W15,$U15-$V15))/SQRT(2)/$AC15*100) | AF15: =IF($AE15="","",ROUND($Z15-$AE15,3)) | AK15: 수동 지정 (직접 입력) | AM15: 0 | AN15: {=IF($AM15=0,0,INDEX($U$72:$U$83,2*$AM15-1))} -> 0 | AO15: {=IF($AM15=0,0,INDEX($U$72:$U$83,2*$AM15))} -> 0 | AP15: {=IF($AM15=0,0,INDEX($AY$72:$AY$83,2*$AM15-1))} -> 0 | AQ15: {=IF($AM15=0,0,INDEX($AY$72:$AY$83,2*$AM15))} -> 0
B16: =IF('2026-07_결과정리'!B6="","",'2026-07_결과정리'!B6) | C16: =IF('2026-07_결과정리'!C6="","",'2026-07_결과정리'!C6) | D16: =IF('2026-07_결과정리'!D6="","",'2026-07_결과정리'!D6) | E16: =IF('2026-07_결과정리'!E6="","",'2026-07_결과정리'!E6) | F16: =IF('2026-07_결과정리'!F6="","",'2026-07_결과정리'!F6) | G16: =IF('2026-07_결과정리'!G6="","",'2026-07_결과정리'!G6) | H16: {=IF($E16="","",IF($AN16=0,AVERAGE($E16:$G16),(SUM($E16:$G16)-INDEX($E16:$G16,$AN16))/2))} | I16: =IF($E16="","",IF($AN16=0,STDEV($E16:$G16),ABS(CHOOSE($AN16,$F16-$G16,$E16-$G16,$E16-$F16))/SQRT(2))) | J16: =IF($H16="","",$I16/$H16*100) | K16: =IF(OR($H16="",$D16=""),"",($H16-$D16)/$D16*100) | L16: =IF(OR($H16="",$D16=""),"",$H16-$D16) | M16: {=IF(OR($E16="",$AM16=0),"",(SUM($E16:$G16)-INDEX($E16:$G16,$AP16))/2)} | N16: =IF($M16="","",$H16-$M16) | O16: =IF($M16="","",ABS(CHOOSE($AP16,$F16-$G16,$E16-$G16,$E16-$F16))/SQRT(2)/$M16*100) | P16: =IF($O16="","",ROUND($J16-$O16,3)) | R16: =IF('2026-07_결과정리'!N6="","",'2026-07_결과정리'!N6) | S16: =IF('2026-07_결과정리'!O6="","",'2026-07_결과정리'!O6) | T16: =IF('2026-07_결과정리'!P6="","",'2026-07_결과정리'!P6) | U16: =IF('2026-07_결과정리'!Q6="","",'2026-07_결과정리'!Q6) | V16: =IF('2026-07_결과정리'!R6="","",'2026-07_결과정리'!R6) | W16: =IF('2026-07_결과정리'!S6="","",'2026-07_결과정리'!S6) | X16: {=IF($U16="","",IF($AO16=0,AVERAGE($U16:$W16),(SUM($U16:$W16)-INDEX($U16:$W16,$AO16))/2))} | Y16: =IF($U16="","",IF($AO16=0,STDEV($U16:$W16),ABS(CHOOSE($AO16,$V16-$W16,$U16-$W16,$U16-$V16))/SQRT(2))) | Z16: =IF($X16="","",$Y16/$X16*100) | AA16: =IF(OR($X16="",$T16=""),"",($X16-$T16)/$T16*100) | AB16: =IF(OR($X16="",$T16=""),"",$X16-$T16) | AC16: {=IF(OR($U16="",$AM16=0),"",(SUM($U16:$W16)-INDEX($U16:$W16,$AQ16))/2)} | AD16: =IF($AC16="","",$X16-$AC16) | AE16: =IF($AC16="","",ABS(CHOOSE($AQ16,$V16-$W16,$U16-$W16,$U16-$V16))/SQRT(2)/$AC16*100) | AF16: =IF($AE16="","",ROUND($Z16-$AE16,3)) | AM16: 0 | AN16: {=IF($AM16=0,0,INDEX($U$72:$U$83,2*$AM16-1))} -> 0 | AO16: {=IF($AM16=0,0,INDEX($U$72:$U$83,2*$AM16))} -> 0 | AP16: {=IF($AM16=0,0,INDEX($AY$72:$AY$83,2*$AM16-1))} -> 0 | AQ16: {=IF($AM16=0,0,INDEX($AY$72:$AY$83,2*$AM16))} -> 0
B17: =IF('2026-07_결과정리'!B7="","",'2026-07_결과정리'!B7) -> BF Control | C17: =IF('2026-07_결과정리'!C7="","",'2026-07_결과정리'!C7) -> CFS 21-01 | D17: =IF('2026-07_결과정리'!D7="","",'2026-07_결과정리'!D7) -> 169.55748 | E17: =IF('2026-07_결과정리'!E7="","",'2026-07_결과정리'!E7) -> 168.76059 | F17: =IF('2026-07_결과정리'!F7="","",'2026-07_결과정리'!F7) -> 171.01706 | G17: =IF('2026-07_결과정리'!G7="","",'2026-07_결과정리'!G7) -> 170.68685 | H17: {=IF($E17="","",IF($AN17=0,AVERAGE($E17:$G17),(SUM($E17:$G17)-INDEX($E17:$G17,$AN17))/2))} -> 170.15483 | I17: =IF($E17="","",IF($AN17=0,STDEV($E17:$G17),ABS(CHOOSE($AN17,$F17-$G17,$E17-$G17,$E17-$F17))/SQRT(2))) -> 1.2186831 | J17: =IF($H17="","",$I17/$H17*100) -> 0.71622008 | K17: =IF(OR($H17="",$D17=""),"",($H17-$D17)/$D17*100) -> 0.35230167 | L17: =IF(OR($H17="",$D17=""),"",$H17-$D17) -> 0.59735383 | M17: {=IF(OR($E17="",$AM17=0),"",(SUM($E17:$G17)-INDEX($E17:$G17,$AP17))/2)} | N17: =IF($M17="","",$H17-$M17) | O17: =IF($M17="","",ABS(CHOOSE($AP17,$F17-$G17,$E17-$G17,$E17-$F17))/SQRT(2)/$M17*100) | P17: =IF($O17="","",ROUND($J17-$O17,3)) | R17: =IF('2026-07_결과정리'!N7="","",'2026-07_결과정리'!N7) -> BF Control | S17: =IF('2026-07_결과정리'!O7="","",'2026-07_결과정리'!O7) -> CFS 21-01 | T17: =IF('2026-07_결과정리'!P7="","",'2026-07_결과정리'!P7) -> 169.55748 | U17: =IF('2026-07_결과정리'!Q7="","",'2026-07_결과정리'!Q7) -> 170.118 | V17: =IF('2026-07_결과정리'!R7="","",'2026-07_결과정리'!R7) -> 171.9292 | W17: =IF('2026-07_결과정리'!S7="","",'2026-07_결과정리'!S7) -> 170.77662 | X17: {=IF($U17="","",IF($AO17=0,AVERAGE($U17:$W17),(SUM($U17:$W17)-INDEX($U17:$W17,$AO17))/2))} -> 170.94127 | Y17: =IF($U17="","",IF($AO17=0,STDEV($U17:$W17),ABS(CHOOSE($AO17,$V17-$W17,$U17-$W17,$U17-$V17))/SQRT(2))) -> 0.91675593 | Z17: =IF($X17="","",$Y17/$X17*100) -> 0.53629876 | AA17: =IF(OR($X17="",$T17=""),"",($X17-$T17)/$T17*100) -> 0.8161204 | AB17: =IF(OR($X17="",$T17=""),"",$X17-$T17) -> 1.3837932 | AC17: {=IF(OR($U17="",$AM17=0),"",(SUM($U17:$W17)-INDEX($U17:$W17,$AQ17))/2)} | AD17: =IF($AC17="","",$X17-$AC17) | AE17: =IF($AC17="","",ABS(CHOOSE($AQ17,$V17-$W17,$U17-$W17,$U17-$V17))/SQRT(2)/$AC17*100) | AF17: =IF($AE17="","",ROUND($Z17-$AE17,3)) | AM17: 0 | AN17: {=IF($AM17=0,0,INDEX($U$72:$U$83,2*$AM17-1))} -> 0 | AO17: {=IF($AM17=0,0,INDEX($U$72:$U$83,2*$AM17))} -> 0 | AP17: {=IF($AM17=0,0,INDEX($AY$72:$AY$83,2*$AM17-1))} -> 0 | AQ17: {=IF($AM17=0,0,INDEX($AY$72:$AY$83,2*$AM17))} -> 0
B18: =IF('2026-07_결과정리'!B8="","",'2026-07_결과정리'!B8) | C18: =IF('2026-07_결과정리'!C8="","",'2026-07_결과정리'!C8) -> Q2 | D18: =IF('2026-07_결과정리'!D8="","",'2026-07_결과정리'!D8) -> 196.2 | E18: =IF('2026-07_결과정리'!E8="","",'2026-07_결과정리'!E8) -> 198.75509 | F18: =IF('2026-07_결과정리'!F8="","",'2026-07_결과정리'!F8) -> 198.75509 | G18: =IF('2026-07_결과정리'!G8="","",'2026-07_결과정리'!G8) -> 198.53495 | H18: {=IF($E18="","",IF($AN18=0,AVERAGE($E18:$G18),(SUM($E18:$G18)-INDEX($E18:$G18,$AN18))/2))} -> 198.68171 | I18: =IF($E18="","",IF($AN18=0,STDEV($E18:$G18),ABS(CHOOSE($AN18,$F18-$G18,$E18-$G18,$E18-$F18))/SQRT(2))) -> 0.12709967 | J18: =IF($H18="","",$I18/$H18*100) -> 0.063971502 | K18: =IF(OR($H18="",$D18=""),"",($H18-$D18)/$D18*100) -> 1.2648878 | L18: =IF(OR($H18="",$D18=""),"",$H18-$D18) -> 2.4817098 | M18: {=IF(OR($E18="",$AM18=0),"",(SUM($E18:$G18)-INDEX($E18:$G18,$AP18))/2)} | N18: =IF($M18="","",$H18-$M18) | O18: =IF($M18="","",ABS(CHOOSE($AP18,$F18-$G18,$E18-$G18,$E18-$F18))/SQRT(2)/$M18*100) | P18: =IF($O18="","",ROUND($J18-$O18,3)) | R18: =IF('2026-07_결과정리'!N8="","",'2026-07_결과정리'!N8) | S18: =IF('2026-07_결과정리'!O8="","",'2026-07_결과정리'!O8) | T18: =IF('2026-07_결과정리'!P8="","",'2026-07_결과정리'!P8) | U18: =IF('2026-07_결과정리'!Q8="","",'2026-07_결과정리'!Q8) | V18: =IF('2026-07_결과정리'!R8="","",'2026-07_결과정리'!R8) | W18: =IF('2026-07_결과정리'!S8="","",'2026-07_결과정리'!S8) | X18: {=IF($U18="","",IF($AO18=0,AVERAGE($U18:$W18),(SUM($U18:$W18)-INDEX($U18:$W18,$AO18))/2))} | Y18: =IF($U18="","",IF($AO18=0,STDEV($U18:$W18),ABS(CHOOSE($AO18,$V18-$W18,$U18-$W18,$U18-$V18))/SQRT(2))) | Z18: =IF($X18="","",$Y18/$X18*100) | AA18: =IF(OR($X18="",$T18=""),"",($X18-$T18)/$T18*100) | AB18: =IF(OR($X18="",$T18=""),"",$X18-$T18) | AC18: {=IF(OR($U18="",$AM18=0),"",(SUM($U18:$W18)-INDEX($U18:$W18,$AQ18))/2)} | AD18: =IF($AC18="","",$X18-$AC18) | AE18: =IF($AC18="","",ABS(CHOOSE($AQ18,$V18-$W18,$U18-$W18,$U18-$V18))/SQRT(2)/$AC18*100) | AF18: =IF($AE18="","",ROUND($Z18-$AE18,3)) | AM18: 0 | AN18: {=IF($AM18=0,0,INDEX($U$72:$U$83,2*$AM18-1))} -> 0 | AO18: {=IF($AM18=0,0,INDEX($U$72:$U$83,2*$AM18))} -> 0 | AP18: {=IF($AM18=0,0,INDEX($AY$72:$AY$83,2*$AM18-1))} -> 0 | AQ18: {=IF($AM18=0,0,INDEX($AY$72:$AY$83,2*$AM18))} -> 0
B19: =IF('2026-07_결과정리'!B9="","",'2026-07_결과정리'!B9) -> BF Sample | C19: =IF('2026-07_결과정리'!C9="","",'2026-07_결과정리'!C9) -> CS 01-01 | D19: =IF('2026-07_결과정리'!D9="","",'2026-07_결과정리'!D9) | E19: =IF('2026-07_결과정리'!E9="","",'2026-07_결과정리'!E9) -> 159.67969 | F19: =IF('2026-07_결과정리'!F9="","",'2026-07_결과정리'!F9) -> 160.17501 | G19: =IF('2026-07_결과정리'!G9="","",'2026-07_결과정리'!G9) -> 159.40451 | H19: {=IF($E19="","",IF($AN19=0,AVERAGE($E19:$G19),(SUM($E19:$G19)-INDEX($E19:$G19,$AN19))/2))} -> 159.78976 | I19: =IF($E19="","",IF($AN19=0,STDEV($E19:$G19),ABS(CHOOSE($AN19,$F19-$G19,$E19-$G19,$E19-$F19))/SQRT(2))) -> 0.54482636 | J19: =IF($H19="","",$I19/$H19*100) -> 0.34096449 | K19: =IF(OR($H19="",$D19=""),"",($H19-$D19)/$D19*100) | L19: =IF(OR($H19="",$D19=""),"",$H19-$D19) | M19: {=IF(OR($E19="",$AM19=0),"",(SUM($E19:$G19)-INDEX($E19:$G19,$AP19))/2)} -> 159.92735 | N19: =IF($M19="","",$H19-$M19) -> -0.13758943 | O19: =IF($M19="","",ABS(CHOOSE($AP19,$F19-$G19,$E19-$G19,$E19-$F19))/SQRT(2)/$M19*100) -> 0.21900288 | P19: =IF($O19="","",ROUND($J19-$O19,3)) -> 0.122 | R19: =IF('2026-07_결과정리'!N9="","",'2026-07_결과정리'!N9) -> BF Sample | S19: =IF('2026-07_결과정리'!O9="","",'2026-07_결과정리'!O9) -> CS 01-01 | T19: =IF('2026-07_결과정리'!P9="","",'2026-07_결과정리'!P9) | U19: =IF('2026-07_결과정리'!Q9="","",'2026-07_결과정리'!Q9) -> 160.4034 | V19: =IF('2026-07_결과정리'!R9="","",'2026-07_결과정리'!R9) -> 160.73271 | W19: =IF('2026-07_결과정리'!S9="","",'2026-07_결과정리'!S9) -> 160.56806 | X19: {=IF($U19="","",IF($AO19=0,AVERAGE($U19:$W19),(SUM($U19:$W19)-INDEX($U19:$W19,$AO19))/2))} -> 160.48573 | Y19: =IF($U19="","",IF($AO19=0,STDEV($U19:$W19),ABS(CHOOSE($AO19,$V19-$W19,$U19-$W19,$U19-$V19))/SQRT(2))) -> 0.11642812 | Z19: =IF($X19="","",$Y19/$X19*100) -> 0.072547335 | AA19: =IF(OR($X19="",$T19=""),"",($X19-$T19)/$T19*100) | AB19: =IF(OR($X19="",$T19=""),"",$X19-$T19) | AC19: {=IF(OR($U19="",$AM19=0),"",(SUM($U19:$W19)-INDEX($U19:$W19,$AQ19))/2)} -> 160.48573 | AD19: =IF($AC19="","",$X19-$AC19) -> 0 | AE19: =IF($AC19="","",ABS(CHOOSE($AQ19,$V19-$W19,$U19-$W19,$U19-$V19))/SQRT(2)/$AC19*100) -> 0.072547335 | AF19: =IF($AE19="","",ROUND($Z19-$AE19,3)) -> 0 | AM19: 1 | AN19: {=IF($AM19=0,0,INDEX($U$72:$U$83,2*$AM19-1))} -> 1 | AO19: {=IF($AM19=0,0,INDEX($U$72:$U$83,2*$AM19))} -> 2 | AP19: {=IF($AM19=0,0,INDEX($AY$72:$AY$83,2*$AM19-1))} -> 3 | AQ19: {=IF($AM19=0,0,INDEX($AY$72:$AY$83,2*$AM19))} -> 2
B20: =IF('2026-07_결과정리'!B10="","",'2026-07_결과정리'!B10) | C20: =IF('2026-07_결과정리'!C10="","",'2026-07_결과정리'!C10) -> CS 01-02 | D20: =IF('2026-07_결과정리'!D10="","",'2026-07_결과정리'!D10) | E20: =IF('2026-07_결과정리'!E10="","",'2026-07_결과정리'!E10) -> 159.78976 | F20: =IF('2026-07_결과정리'!F10="","",'2026-07_결과정리'!F10) -> 160.34012 | G20: =IF('2026-07_결과정리'!G10="","",'2026-07_결과정리'!G10) -> 160.00991 | H20: {=IF($E20="","",IF($AN20=0,AVERAGE($E20:$G20),(SUM($E20:$G20)-INDEX($E20:$G20,$AN20))/2))} -> 160.17501 | I20: =IF($E20="","",IF($AN20=0,STDEV($E20:$G20),ABS(CHOOSE($AN20,$F20-$G20,$E20-$G20,$E20-$F20))/SQRT(2))) -> 0.23349701 | J20: =IF($H20="","",$I20/$H20*100) -> 0.14577618 | K20: =IF(OR($H20="",$D20=""),"",($H20-$D20)/$D20*100) | L20: =IF(OR($H20="",$D20=""),"",$H20-$D20) | M20: {=IF(OR($E20="",$AM20=0),"",(SUM($E20:$G20)-INDEX($E20:$G20,$AP20))/2)} -> 160.17501 | N20: =IF($M20="","",$H20-$M20) -> 0 | O20: =IF($M20="","",ABS(CHOOSE($AP20,$F20-$G20,$E20-$G20,$E20-$F20))/SQRT(2)/$M20*100) -> 0.14577618 | P20: =IF($O20="","",ROUND($J20-$O20,3)) -> 0 | R20: =IF('2026-07_결과정리'!N10="","",'2026-07_결과정리'!N10) | S20: =IF('2026-07_결과정리'!O10="","",'2026-07_결과정리'!O10) -> CS 01-02 | T20: =IF('2026-07_결과정리'!P10="","",'2026-07_결과정리'!P10) | U20: =IF('2026-07_결과정리'!Q10="","",'2026-07_결과정리'!Q10) -> 161.17179 | V20: =IF('2026-07_결과정리'!R10="","",'2026-07_결과정리'!R10) -> 160.7876 | W20: =IF('2026-07_결과정리'!S10="","",'2026-07_결과정리'!S10) -> 159.74479 | X20: {=IF($U20="","",IF($AO20=0,AVERAGE($U20:$W20),(SUM($U20:$W20)-INDEX($U20:$W20,$AO20))/2))} -> 160.26619 | Y20: =IF($U20="","",IF($AO20=0,STDEV($U20:$W20),ABS(CHOOSE($AO20,$V20-$W20,$U20-$W20,$U20-$V20))/SQRT(2))) -> 0.73737809 | Z20: =IF($X20="","",$Y20/$X20*100) -> 0.46009585 | AA20: =IF(OR($X20="",$T20=""),"",($X20-$T20)/$T20*100) | AB20: =IF(OR($X20="",$T20=""),"",$X20-$T20) | AC20: {=IF(OR($U20="",$AM20=0),"",(SUM($U20:$W20)-INDEX($U20:$W20,$AQ20))/2)} -> 160.97969 | AD20: =IF($AC20="","",$X20-$AC20) -> -0.71350165 | AE20: =IF($AC20="","",ABS(CHOOSE($AQ20,$V20-$W20,$U20-$W20,$U20-$V20))/SQRT(2)/$AC20*100) -> 0.16875769 | AF20: =IF($AE20="","",ROUND($Z20-$AE20,3)) -> 0.291 | AM20: 2 | AN20: {=IF($AM20=0,0,INDEX($U$72:$U$83,2*$AM20-1))} -> 1 | AO20: {=IF($AM20=0,0,INDEX($U$72:$U$83,2*$AM20))} -> 1 | AP20: {=IF($AM20=0,0,INDEX($AY$72:$AY$83,2*$AM20-1))} -> 1 | AQ20: {=IF($AM20=0,0,INDEX($AY$72:$AY$83,2*$AM20))} -> 3
B21: =IF('2026-07_결과정리'!B11="","",'2026-07_결과정리'!B11) | C21: =IF('2026-07_결과정리'!C11="","",'2026-07_결과정리'!C11) -> CS 02-01 | D21: =IF('2026-07_결과정리'!D11="","",'2026-07_결과정리'!D11) | E21: =IF('2026-07_결과정리'!E11="","",'2026-07_결과정리'!E11) -> 239.81178 | F21: =IF('2026-07_결과정리'!F11="","",'2026-07_결과정리'!F11) -> 240.85746 | G21: =IF('2026-07_결과정리'!G11="","",'2026-07_결과정리'!G11) -> 239.81178 | H21: {=IF($E21="","",IF($AN21=0,AVERAGE($E21:$G21),(SUM($E21:$G21)-INDEX($E21:$G21,$AN21))/2))} -> 240.33462 | I21: =IF($E21="","",IF($AN21=0,STDEV($E21:$G21),ABS(CHOOSE($AN21,$F21-$G21,$E21-$G21,$E21-$F21))/SQRT(2))) -> 0.7394072 | J21: =IF($H21="","",$I21/$H21*100) -> 0.30765739 | K21: =IF(OR($H21="",$D21=""),"",($H21-$D21)/$D21*100) | L21: =IF(OR($H21="",$D21=""),"",$H21-$D21) | M21: {=IF(OR($E21="",$AM21=0),"",(SUM($E21:$G21)-INDEX($E21:$G21,$AP21))/2)} -> 240.33462 | N21: =IF($M21="","",$H21-$M21) -> 0 | O21: =IF($M21="","",ABS(CHOOSE($AP21,$F21-$G21,$E21-$G21,$E21-$F21))/SQRT(2)/$M21*100) -> 0.30765739 | P21: =IF($O21="","",ROUND($J21-$O21,3)) -> 0 | R21: =IF('2026-07_결과정리'!N11="","",'2026-07_결과정리'!N11) | S21: =IF('2026-07_결과정리'!O11="","",'2026-07_결과정리'!O11) -> CS 02-01 | T21: =IF('2026-07_결과정리'!P11="","",'2026-07_결과정리'!P11) | U21: =IF('2026-07_결과정리'!Q11="","",'2026-07_결과정리'!Q11) -> 240.42536 | V21: =IF('2026-07_결과정리'!R11="","",'2026-07_결과정리'!R11) -> 240.37047 | W21: =IF('2026-07_결과정리'!S11="","",'2026-07_결과정리'!S11) -> 240.59001 | X21: {=IF($U21="","",IF($AO21=0,AVERAGE($U21:$W21),(SUM($U21:$W21)-INDEX($U21:$W21,$AO21))/2))} -> 240.50768 | Y21: =IF($U21="","",IF($AO21=0,STDEV($U21:$W21),ABS(CHOOSE($AO21,$V21-$W21,$U21-$W21,$U21-$V21))/SQRT(2))) -> 0.11642812 | Z21: =IF($X21="","",$Y21/$X21*100) -> 0.048409314 | AA21: =IF(OR($X21="",$T21=""),"",($X21-$T21)/$T21*100) | AB21: =IF(OR($X21="",$T21=""),"",$X21-$T21) | AC21: {=IF(OR($U21="",$AM21=0),"",(SUM($U21:$W21)-INDEX($U21:$W21,$AQ21))/2)} -> 240.50768 | AD21: =IF($AC21="","",$X21-$AC21) -> 0 | AE21: =IF($AC21="","",ABS(CHOOSE($AQ21,$V21-$W21,$U21-$W21,$U21-$V21))/SQRT(2)/$AC21*100) -> 0.048409314 | AF21: =IF($AE21="","",ROUND($Z21-$AE21,3)) -> 0 | AM21: 3 | AN21: {=IF($AM21=0,0,INDEX($U$72:$U$83,2*$AM21-1))} -> 3 | AO21: {=IF($AM21=0,0,INDEX($U$72:$U$83,2*$AM21))} -> 2 | AP21: {=IF($AM21=0,0,INDEX($AY$72:$AY$83,2*$AM21-1))} -> 1 | AQ21: {=IF($AM21=0,0,INDEX($AY$72:$AY$83,2*$AM21))} -> 2
B22: =IF('2026-07_결과정리'!B12="","",'2026-07_결과정리'!B12) | C22: =IF('2026-07_결과정리'!C12="","",'2026-07_결과정리'!C12) -> CS 02-02 | D22: =IF('2026-07_결과정리'!D12="","",'2026-07_결과정리'!D12) | E22: =IF('2026-07_결과정리'!E12="","",'2026-07_결과정리'!E12) -> 240.3071 | F22: =IF('2026-07_결과정리'!F12="","",'2026-07_결과정리'!F12) -> 239.70171 | G22: =IF('2026-07_결과정리'!G12="","",'2026-07_결과정리'!G12) -> 240.52724 | H22: {=IF($E22="","",IF($AN22=0,AVERAGE($E22:$G22),(SUM($E22:$G22)-INDEX($E22:$G22,$AN22))/2))} -> 240.11447 | I22: =IF($E22="","",IF($AN22=0,STDEV($E22:$G22),ABS(CHOOSE($AN22,$F22-$G22,$E22-$G22,$E22-$F22))/SQRT(2))) -> 0.58374253 | J22: =IF($H22="","",$I22/$H22*100) -> 0.2431101 | K22: =IF(OR($H22="",$D22=""),"",($H22-$D22)/$D22*100) | L22: =IF(OR($H22="",$D22=""),"",$H22-$D22) | M22: {=IF(OR($E22="",$AM22=0),"",(SUM($E22:$G22)-INDEX($E22:$G22,$AP22))/2)} -> 240.41717 | N22: =IF($M22="","",$H22-$M22) -> -0.30269675 | O22: =IF($M22="","",ABS(CHOOSE($AP22,$F22-$G22,$E22-$G22,$E22-$F22))/SQRT(2)/$M22*100) -> 0.064747735 | P22: =IF($O22="","",ROUND($J22-$O22,3)) -> 0.178 | R22: =IF('2026-07_결과정리'!N12="","",'2026-07_결과정리'!N12) | S22: =IF('2026-07_결과정리'!O12="","",'2026-07_결과정리'!O12) -> CS 02-02 | T22: =IF('2026-07_결과정리'!P12="","",'2026-07_결과정리'!P12) | U22: =IF('2026-07_결과정리'!Q12="","",'2026-07_결과정리'!Q12) -> 241.63282 | V22: =IF('2026-07_결과정리'!R12="","",'2026-07_결과정리'!R12) -> 241.08397 | W22: =IF('2026-07_결과정리'!S12="","",'2026-07_결과정리'!S12) -> 242.7854 | X22: {=IF($U22="","",IF($AO22=0,AVERAGE($U22:$W22),(SUM($U22:$W22)-INDEX($U22:$W22,$AO22))/2))} -> 241.3584 | Y22: =IF($U22="","",IF($AO22=0,STDEV($U22:$W22),ABS(CHOOSE($AO22,$V22-$W22,$U22-$W22,$U22-$V22))/SQRT(2))) -> 0.38809373 | Z22: =IF($X22="","",$Y22/$X22*100) -> 0.16079562 | AA22: =IF(OR($X22="",$T22=""),"",($X22-$T22)/$T22*100) | AB22: =IF(OR($X22="",$T22=""),"",$X22-$T22) | AC22: {=IF(OR($U22="",$AM22=0),"",(SUM($U22:$W22)-INDEX($U22:$W22,$AQ22))/2)} -> 241.3584 | AD22: =IF($AC22="","",$X22-$AC22) -> 0 | AE22: =IF($AC22="","",ABS(CHOOSE($AQ22,$V22-$W22,$U22-$W22,$U22-$V22))/SQRT(2)/$AC22*100) -> 0.16079562 | AF22: =IF($AE22="","",ROUND($Z22-$AE22,3)) -> 0 | AM22: 4 | AN22: {=IF($AM22=0,0,INDEX($U$72:$U$83,2*$AM22-1))} -> 1 | AO22: {=IF($AM22=0,0,INDEX($U$72:$U$83,2*$AM22))} -> 3 | AP22: {=IF($AM22=0,0,INDEX($AY$72:$AY$83,2*$AM22-1))} -> 2 | AQ22: {=IF($AM22=0,0,INDEX($AY$72:$AY$83,2*$AM22))} -> 3
B23: =IF('2026-07_결과정리'!B13="","",'2026-07_결과정리'!B13) | C23: =IF('2026-07_결과정리'!C13="","",'2026-07_결과정리'!C13) -> CS 03-01 | D23: =IF('2026-07_결과정리'!D13="","",'2026-07_결과정리'!D13) | E23: =IF('2026-07_결과정리'!E13="","",'2026-07_결과정리'!E13) -> 132.7672 | F23: =IF('2026-07_결과정리'!F13="","",'2026-07_결과정리'!F13) -> 132.49202 | G23: =IF('2026-07_결과정리'!G13="","",'2026-07_결과정리'!G13) -> 132.49202 | H23: {=IF($E23="","",IF($AN23=0,AVERAGE($E23:$G23),(SUM($E23:$G23)-INDEX($E23:$G23,$AN23))/2))} -> 132.62961 | I23: =IF($E23="","",IF($AN23=0,STDEV($E23:$G23),ABS(CHOOSE($AN23,$F23-$G23,$E23-$G23,$E23-$F23))/SQRT(2))) -> 0.19458084 | J23: =IF($H23="","",$I23/$H23*100) -> 0.14670996 | K23: =IF(OR($H23="",$D23=""),"",($H23-$D23)/$D23*100) | L23: =IF(OR($H23="",$D23=""),"",$H23-$D23) | M23: {=IF(OR($E23="",$AM23=0),"",(SUM($E23:$G23)-INDEX($E23:$G23,$AP23))/2)} -> 132.62961 | N23: =IF($M23="","",$H23-$M23) -> 0 | O23: =IF($M23="","",ABS(CHOOSE($AP23,$F23-$G23,$E23-$G23,$E23-$F23))/SQRT(2)/$M23*100) -> 0.14670996 | P23: =IF($O23="","",ROUND($J23-$O23,3)) -> 0 | R23: =IF('2026-07_결과정리'!N13="","",'2026-07_결과정리'!N13) | S23: =IF('2026-07_결과정리'!O13="","",'2026-07_결과정리'!O13) -> CS 03-01 | T23: =IF('2026-07_결과정리'!P13="","",'2026-07_결과정리'!P13) | U23: =IF('2026-07_결과정리'!Q13="","",'2026-07_결과정리'!Q13) -> 131.14984 | V23: =IF('2026-07_결과정리'!R13="","",'2026-07_결과정리'!R13) -> 131.2596 | W23: =IF('2026-07_결과정리'!S13="","",'2026-07_결과정리'!S13) -> 131.69868 | X23: {=IF($U23="","",IF($AO23=0,AVERAGE($U23:$W23),(SUM($U23:$W23)-INDEX($U23:$W23,$AO23))/2))} -> 131.42426 | Y23: =IF($U23="","",IF($AO23=0,STDEV($U23:$W23),ABS(CHOOSE($AO23,$V23-$W23,$U23-$W23,$U23-$V23))/SQRT(2))) -> 0.38809373 | Z23: =IF($X23="","",$Y23/$X23*100) -> 0.2952984 | AA23: =IF(OR($X23="",$T23=""),"",($X23-$T23)/$T23*100) | AB23: =IF(OR($X23="",$T23=""),"",$X23-$T23) | AC23: {=IF(OR($U23="",$AM23=0),"",(SUM($U23:$W23)-INDEX($U23:$W23,$AQ23))/2)} -> 131.47914 | AD23: =IF($AC23="","",$X23-$AC23) -> -0.054884742 | AE23: =IF($AC23="","",ABS(CHOOSE($AQ23,$V23-$W23,$U23-$W23,$U23-$V23))/SQRT(2)/$AC23*100) -> 0.2361401 | AF23: =IF($AE23="","",ROUND($Z23-$AE23,3)) -> 0.059 | AM23: 5 | AN23: {=IF($AM23=0,0,INDEX($U$72:$U$83,2*$AM23-1))} -> 3 | AO23: {=IF($AM23=0,0,INDEX($U$72:$U$83,2*$AM23))} -> 2 | AP23: {=IF($AM23=0,0,INDEX($AY$72:$AY$83,2*$AM23-1))} -> 2 | AQ23: {=IF($AM23=0,0,INDEX($AY$72:$AY$83,2*$AM23))} -> 1
